Workbook

Sheet DASHBOARD
A2: DASHBOARD ASET BRA 2026
A3: Ringkasan otomatis dari sheet "List Data Aset BRA" dan "ASSET DIJUAL"
A5: TOTAL ASET | E5: STATUS AKTIF | I5: STATUS STANDBY | M5: PROJECT TERDATA
A6: =COUNTIF('List Data Aset BRA'!A6:A341,">0") -> 314 | E6: =COUNTIF('List Data Aset BRA'!C6:O345,"AKTIF") -> 245 | I6: =COUNTIF('List Data Aset BRA'!O6:O341,"STANDBY") -> 52 | M6: =COUNTA(S39:S67) -> 12
A10: RATA-RATA USIA ASET | E10: TANPA STATUS | I10: ASET DIJUAL | M10: NILAI ASET YANG TELAH TER JUAL
A11: =AVERAGE('List Data Aset BRA'!W6:W350) -> 4.1889251 | E11: =COUNTIF('List Data Aset BRA'!M6:M341,"YARD DURI") -> 11 | I11: ='ASSET DIJUAL'!C56 -> 30 | M11: ='ASSET DIJUAL'!I56 -> 7183000002
A38: KPI | B38: Value | D38: Status | E38: Jumlah | G38: Bucket Usia | H38: Jumlah | J38: Kategori | K38: Jumlah | M38: Project | N38: Jumlah | P38: Tahun Jual | Q38: Jumlah | S38: Semua Project
A39: Total Asset | B39: =COUNTIF('List Data Aset BRA'!A6:A341,">0") -> 314 | D39: AKTIF | E39: =COUNTIF('List Data Aset BRA'!C6:O345,"AKTIF") -> 245 | G39: 0-2 th | H39: =COUNTIF('List Data Aset BRA'!W6:W345,"0-2 th") -> 0 | J39: DUMPTRUCK | K39: =COUNTIF('List Data Aset BRA'!X6:X445,J39) -> 123 | M39: WUR EW | N39: 110 | P39: 2024 | Q39: 6 | S39: ADERA
A40: Status Aktif | B40: =COUNTIF('List Data Aset BRA'!O6:O341,"AKTIF") -> 245 | D40: STANDBY | E40: =COUNTIF('List Data Aset BRA'!C6:O345,"STANDBY") -> 52 | G40: 3-5 th | H40: =COUNTIF('List Data Aset BRA'!W6:W345,"3-5 th") -> 0 | J40: KENDARAAN OPERASIONAL | K40: =COUNTIF('List Data Aset BRA'!X6:X446,J40) -> 60 | M40: STANBY YARD | N40: 24 | P40: 2025 | Q40: 11 | S40: ASR
A41: Status Standby | B41: =COUNTIF('List Data Aset BRA'!O6:O341,"STANDBY") -> 52 | G41: 6-10 th | H41: =COUNTIF('List Data Aset BRA'!W6:W345,"6-10 th") -> 0 | J41: EXCAVATOR | K41: =COUNTIF('List Data Aset BRA'!X6:X447,J41) -> 27 | M41: RWI | N41: 23 | P41: 2026 | Q41: 2 | S41: BANGKO
A42: Tanpa Status | B42: =COUNTIF('List Data Aset BRA'!O6:O345,"(KOSONG)") -> 0 | G42: >10 th | H42: =COUNTIF('List Data Aset BRA'!W6:W345,">10 th") -> 1 | J42: VIBROROLLER | K42: =COUNTIF('List Data Aset BRA'!X6:X448,J42) -> 21 | M42: ADERA | N42: 18 | S42: DURI
B43: =SUM(B40:B42) -> 297 | G43: Tanpa tahun | H43: =COUNTIF('List Data Aset BRA'!W6:W345,"Tanpa tahun") -> 0 | J43: BULLDOZER | K43: =COUNTIF('List Data Aset BRA'!X6:X449,J43) -> 8 | M43: PERTAMINA EP | N43: 17 | S43: KSO BRA-BKP
A44: Project Terdata | B44: =COUNTA(S39:S67) -> 12 | J44: SEPEDA MOTOR | K44: =COUNTIF('List Data Aset BRA'!X6:X450,J44) -> 9 | M44: MATTING BOARD | N44: 17 | S44: MATTING BOARD
A45: Rata-rata Usia | B45: =AVERAGE('List Data Aset BRA'!W6:W350) -> 4.1889251 | J45: TMC | K45: =COUNTIF('List Data Aset BRA'!X6:X451,J45) -> 7 | M45: YARD DURI | N45: 7 | S45: PERTAGAS
A46: Aset Dijual | B46: ='ASSET DIJUAL'!C56 -> 30 | J46: TOTAL STATION DAN WATER PASS | K46: =COUNTIF('List Data Aset BRA'!X6:X452,J46) -> 11 | M46: ASR | N46: 6 | S46: PERTAMINA EP
A47: Nilai Jual Tercatat | B47: Rp 5.183.000.002 | J47: FLATDECK | K47: =COUNTIF('List Data Aset BRA'!X6:X454,J47) -> 0 | M47: KENDARI | N47: 12 | S47: RWI
J48: MOTOR GRADER | K48: =COUNTIF('List Data Aset BRA'!X6:X455,J48) -> 9 | M48: TOL JAMBI | N48: 6 | S48: SEWA KELMI
J49: PRIMOVER DAN LOWBED | K49: =COUNTIF('List Data Aset BRA'!X6:X467,J49) -> 0 | M49: YARD PALEMBANG | N49: 5 | S49: WUR EW
J50: BACKHOE LOADER | K50: =COUNTIF('List Data Aset BRA'!X6:X457,J50) -> 2 | S50: KENDARI
J51: WHEEL LOADER | K51: =COUNTIF('List Data Aset BRA'!X6:X458,J51) -> 4
J52: CRAWLER CRANE | K52: =COUNTIF('List Data Aset BRA'!X6:X459,J52) -> 2
J53: RECYCLING MACHINE | K53: =COUNTIF('List Data Aset BRA'!X6:X460,J53) -> 3
J54: SPREADER | K54: =COUNTIF('List Data Aset BRA'!X6:X461,J54) -> 0
J55: BREAKER | K55: =COUNTIF('List Data Aset BRA'!X6:X462,J55) -> 1
J56: MEDIUM BUS | K56: 3
J57: Truck Box Allumunium | K57: 1
J58: TRADO | K58: =COUNTIF('List Data Aset BRA'!X6:X466,J58) -> 4
J59: WATER TANK | K59: =COUNTIF('List Data Aset BRA'!X6:X468,J59) -> 6
J60: FUEL TANK | K60: =COUNTIF('List Data Aset BRA'!X6:X469,J60) -> 1
K62: =SUM(K39:K60) -> 302
A64: JUMLAH ALAT AKTIF/STANDBY PER PROJECT
A65: ALAT | B65: STATUS | C65: PROJECT
C66: ADERA | D66: ASR | E66: WUR EW | F66: PERTAGAS | G66: EQUIPMENT | H66: KENDARI | I66: MATTING BOARD | J66: YARD DURI | K66: RWI | L66: TOL JAMBI | M66: HO | N66: MUARA ENIM | O66: SAWIT ROHUL | P66: YARD PALEMBANG | Q66: USER PHR | R66: PEKANBARU
A67: VIBRO | B67: AKTIF | C67: =COUNTIFS('List Data Aset BRA'!$B:$B,$A67,'List Data Aset BRA'!$M:$M,C$66,'List Data Aset BRA'!$O:$O,$B67) -> 2 | D67: =COUNTIFS('List Data Aset BRA'!$B:$B,$A67,'List Data Aset BRA'!$M:$M,D$66,'List Data Aset BRA'!$O:$O,$B67) -> 0 | E67: =COUNTIFS('List Data Aset BRA'!$B:$B,$A67,'List Data Aset BRA'!$M:$M,E$66,'List Data Aset BRA'!$O:$O,$B67) -> 8 | F67: =COUNTIFS('List Data Aset BRA'!$B:$B,$A67,'List Data Aset BRA'!$M:$M,F$66,'List Data Aset BRA'!$O:$O,$B67) -> 0 | G67: =COUNTIFS('List Data Aset BRA'!$B:$B,$A67,'List Data Aset BRA'!$M:$M,G$66,'List Data Aset BRA'!$O:$O,$B67) -> 0 | H67: =COUNTIFS('List Data Aset BRA'!$B:$B,$A67,'List Data Aset BRA'!$M:$M,H$66,'List Data Aset BRA'!$O:$O,$B67) -> 0 | I67: =COUNTIFS('List Data Aset BRA'!$B:$B,$A67,'List Data Aset BRA'!$M:$M,I$66,'List Data Aset BRA'!$O:$O,$B67) -> 0 | J67: =COUNTIFS('List Data Aset BRA'!$B:$B,$A67,'List Data Aset BRA'!$M:$M,J$66,'List Data Aset BRA'!$O:$O,$B67) -> 0 | ... R67: =COUNTIFS('List Data Aset BRA'!$B:$B,$A67,'List Data Aset BRA'!$M:$M,R$66,'List Data Aset BRA'!$O:$O,$B67) -> 0
A68: VIBRO | B68: STANDBY | C68: =COUNTIFS('List Data Aset BRA'!$B:$B,$A68,'List Data Aset BRA'!$M:$M,C$66,'List Data Aset BRA'!$O:$O,$B68) -> 0 | D68: =COUNTIFS('List Data Aset BRA'!$B:$B,$A68,'List Data Aset BRA'!$M:$M,D$66,'List Data Aset BRA'!$O:$O,$B68) -> 0 | E68: =COUNTIFS('List Data Aset BRA'!$B:$B,$A68,'List Data Aset BRA'!$M:$M,E$66,'List Data Aset BRA'!$O:$O,$B68) -> 1 | F68: =COUNTIFS('List Data Aset BRA'!$B:$B,$A68,'List Data Aset BRA'!$M:$M,F$66,'List Data Aset BRA'!$O:$O,$B68) -> 0 | G68: =COUNTIFS('List Data Aset BRA'!$B:$B,$A68,'List Data Aset BRA'!$M:$M,G$66,'List Data Aset BRA'!$O:$O,$B68) -> 0 | H68: =COUNTIFS('List Data Aset BRA'!$B:$B,$A68,'List Data Aset BRA'!$M:$M,H$66,'List Data Aset BRA'!$O:$O,$B68) -> 0 | I68: =COUNTIFS('List Data Aset BRA'!$B:$B,$A68,'List Data Aset BRA'!$M:$M,I$66,'List Data Aset BRA'!$O:$O,$B68) -> 0 | J68: =COUNTIFS('List Data Aset BRA'!$B:$B,$A68,'List Data Aset BRA'!$M:$M,J$66,'List Data Aset BRA'!$O:$O,$B68) -> 0 | ... R68: =COUNTIFS('List Data Aset BRA'!$B:$B,$A68,'List Data Aset BRA'!$M:$M,R$66,'List Data Aset BRA'!$O:$O,$B68) -> 0
A69: MOTOR GRADER | B69: AKTIF | C69: =COUNTIFS('List Data Aset BRA'!$B:$B,$A69,'List Data Aset BRA'!$M:$M,C$66,'List Data Aset BRA'!$O:$O,$B69) -> 2 | D69: =COUNTIFS('List Data Aset BRA'!$B:$B,$A69,'List Data Aset BRA'!$M:$M,D$66,'List Data Aset BRA'!$O:$O,$B69) -> 0 | E69: =COUNTIFS('List Data Aset BRA'!$B:$B,$A69,'List Data Aset BRA'!$M:$M,E$66,'List Data Aset BRA'!$O:$O,$B69) -> 2 | F69: =COUNTIFS('List Data Aset BRA'!$B:$B,$A69,'List Data Aset BRA'!$M:$M,F$66,'List Data Aset BRA'!$O:$O,$B69) -> 0 | G69: =COUNTIFS('List Data Aset BRA'!$B:$B,$A69,'List Data Aset BRA'!$M:$M,G$66,'List Data Aset BRA'!$O:$O,$B69) -> 0 | H69: =COUNTIFS('List Data Aset BRA'!$B:$B,$A69,'List Data Aset BRA'!$M:$M,H$66,'List Data Aset BRA'!$O:$O,$B69) -> 1 | I69: =COUNTIFS('List Data Aset BRA'!$B:$B,$A69,'List Data Aset BRA'!$M:$M,I$66,'List Data Aset BRA'!$O:$O,$B69) -> 0 | J69: =COUNTIFS('List Data Aset BRA'!$B:$B,$A69,'List Data Aset BRA'!$M:$M,J$66,'List Data Aset BRA'!$O:$O,$B69) -> 0 | ... R69: =COUNTIFS('List Data Aset BRA'!$B:$B,$A69,'List Data Aset BRA'!$M:$M,R$66,'List Data Aset BRA'!$O:$O,$B69) -> 0
A70: MOTOR GRADER | B70: STANDBY | C70: =COUNTIFS('List Data Aset BRA'!$B:$B,$A70,'List Data Aset BRA'!$M:$M,C$66,'List Data Aset BRA'!$O:$O,$B70) -> 0 | D70: =COUNTIFS('List Data Aset BRA'!$B:$B,$A70,'List Data Aset BRA'!$M:$M,D$66,'List Data Aset BRA'!$O:$O,$B70) -> 0 | E70: =COUNTIFS('List Data Aset BRA'!$B:$B,$A70,'List Data Aset BRA'!$M:$M,E$66,'List Data Aset BRA'!$O:$O,$B70) -> 0 | F70: =COUNTIFS('List Data Aset BRA'!$B:$B,$A70,'List Data Aset BRA'!$M:$M,F$66,'List Data Aset BRA'!$O:$O,$B70) -> 0 | G70: =COUNTIFS('List Data Aset BRA'!$B:$B,$A70,'List Data Aset BRA'!$M:$M,G$66,'List Data Aset BRA'!$O:$O,$B70) -> 0 | H70: =COUNTIFS('List Data Aset BRA'!$B:$B,$A70,'List Data Aset BRA'!$M:$M,H$66,'List Data Aset BRA'!$O:$O,$B70) -> 0 | I70: =COUNTIFS('List Data Aset BRA'!$B:$B,$A70,'List Data Aset BRA'!$M:$M,I$66,'List Data Aset BRA'!$O:$O,$B70) -> 0 | J70: =COUNTIFS('List Data Aset BRA'!$B:$B,$A70,'List Data Aset BRA'!$M:$M,J$66,'List Data Aset BRA'!$O:$O,$B70) -> 0 | ... R70: =COUNTIFS('List Data Aset BRA'!$B:$B,$A70,'List Data Aset BRA'!$M:$M,R$66,'List Data Aset BRA'!$O:$O,$B70) -> 0
A71: BULLDOZER | B71: AKTIF | C71: =COUNTIFS('List Data Aset BRA'!$B:$B,$A71,'List Data Aset BRA'!$M:$M,C$66,'List Data Aset BRA'!$O:$O,$B71) -> 1 | D71: =COUNTIFS('List Data Aset BRA'!$B:$B,$A71,'List Data Aset BRA'!$M:$M,D$66,'List Data Aset BRA'!$O:$O,$B71) -> 0 | E71: =COUNTIFS('List Data Aset BRA'!$B:$B,$A71,'List Data Aset BRA'!$M:$M,E$66,'List Data Aset BRA'!$O:$O,$B71) -> 4 | F71: =COUNTIFS('List Data Aset BRA'!$B:$B,$A71,'List Data Aset BRA'!$M:$M,F$66,'List Data Aset BRA'!$O:$O,$B71) -> 0 | G71: =COUNTIFS('List Data Aset BRA'!$B:$B,$A71,'List Data Aset BRA'!$M:$M,G$66,'List Data Aset BRA'!$O:$O,$B71) -> 0 | H71: =COUNTIFS('List Data Aset BRA'!$B:$B,$A71,'List Data Aset BRA'!$M:$M,H$66,'List Data Aset BRA'!$O:$O,$B71) -> 1 | I71: =COUNTIFS('List Data Aset BRA'!$B:$B,$A71,'List Data Aset BRA'!$M:$M,I$66,'List Data Aset BRA'!$O:$O,$B71) -> 0 | J71: =COUNTIFS('List Data Aset BRA'!$B:$B,$A71,'List Data Aset BRA'!$M:$M,J$66,'List Data Aset BRA'!$O:$O,$B71) -> 0 | ... R71: =COUNTIFS('List Data Aset BRA'!$B:$B,$A71,'List Data Aset BRA'!$M:$M,R$66,'List Data Aset BRA'!$O:$O,$B71) -> 0
A72: BULLDOZER | B72: STANDBY | C72: =COUNTIFS('List Data Aset BRA'!$B:$B,$A72,'List Data Aset BRA'!$M:$M,C$66,'List Data Aset BRA'!$O:$O,$B72) -> 0 | D72: =COUNTIFS('List Data Aset BRA'!$B:$B,$A72,'List Data Aset BRA'!$M:$M,D$66,'List Data Aset BRA'!$O:$O,$B72) -> 0 | E72: =COUNTIFS('List Data Aset BRA'!$B:$B,$A72,'List Data Aset BRA'!$M:$M,E$66,'List Data Aset BRA'!$O:$O,$B72) -> 0 | F72: =COUNTIFS('List Data Aset BRA'!$B:$B,$A72,'List Data Aset BRA'!$M:$M,F$66,'List Data Aset BRA'!$O:$O,$B72) -> 0 | G72: =COUNTIFS('List Data Aset BRA'!$B:$B,$A72,'List Data Aset BRA'!$M:$M,G$66,'List Data Aset BRA'!$O:$O,$B72) -> 0 | H72: =COUNTIFS('List Data Aset BRA'!$B:$B,$A72,'List Data Aset BRA'!$M:$M,H$66,'List Data Aset BRA'!$O:$O,$B72) -> 0 | I72: =COUNTIFS('List Data Aset BRA'!$B:$B,$A72,'List Data Aset BRA'!$M:$M,I$66,'List Data Aset BRA'!$O:$O,$B72) -> 0 | J72: =COUNTIFS('List Data Aset BRA'!$B:$B,$A72,'List Data Aset BRA'!$M:$M,J$66,'List Data Aset BRA'!$O:$O,$B72) -> 0 | ... R72: =COUNTIFS('List Data Aset BRA'!$B:$B,$A72,'List Data Aset BRA'!$M:$M,R$66,'List Data Aset BRA'!$O:$O,$B72) -> 0
A73: EXCAVATOR | B73: AKTIF | C73: =COUNTIFS('List Data Aset BRA'!$B:$B,$A73,'List Data Aset BRA'!$M:$M,C$66,'List Data Aset BRA'!$O:$O,$B73) -> 2 | D73: =COUNTIFS('List Data Aset BRA'!$B:$B,$A73,'List Data Aset BRA'!$M:$M,D$66,'List Data Aset BRA'!$O:$O,$B73) -> 1 | E73: =COUNTIFS('List Data Aset BRA'!$B:$B,$A73,'List Data Aset BRA'!$M:$M,E$66,'List Data Aset BRA'!$O:$O,$B73) -> 12 | F73: =COUNTIFS('List Data Aset BRA'!$B:$B,$A73,'List Data Aset BRA'!$M:$M,F$66,'List Data Aset BRA'!$O:$O,$B73) -> 0 | G73: =COUNTIFS('List Data Aset BRA'!$B:$B,$A73,'List Data Aset BRA'!$M:$M,G$66,'List Data Aset BRA'!$O:$O,$B73) -> 0 | H73: =COUNTIFS('List Data Aset BRA'!$B:$B,$A73,'List Data Aset BRA'!$M:$M,H$66,'List Data Aset BRA'!$O:$O,$B73) -> 7 | I73: =COUNTIFS('List Data Aset BRA'!$B:$B,$A73,'List Data Aset BRA'!$M:$M,I$66,'List Data Aset BRA'!$O:$O,$B73) -> 0 | J73: =COUNTIFS('List Data Aset BRA'!$B:$B,$A73,'List Data Aset BRA'!$M:$M,J$66,'List Data Aset BRA'!$O:$O,$B73) -> 0 | ... R73: =COUNTIFS('List Data Aset BRA'!$B:$B,$A73,'List Data Aset BRA'!$M:$M,R$66,'List Data Aset BRA'!$O:$O,$B73) -> 1
...

Sheet List Data Aset BRA
A2: REKAP HEAVY EQUIPMENT DAN VEHICLE PT BINA REKAYASA ANUGRAH
A4: No | C4: Nama Asset | D4: Dealer | E4: Tahun Pembuatan | F4: Tahun Invoice/Dok | G4: No Polisi/Serial Number | H4: Status Warranty | I4: Kapasitas | J4: Kode Unit | K4: Nama Operator | L4: Nomor Lambung Aktual | M4: PROJECT | N4: LOKASI | O4: Status | P4: Update Status | Q4: LOKASI INVOICE | R4: STATUS LUNAS/LEASING | W4: USIA | X4: Kategori Clean
A5: A | B5: JENIS ALAT | C5: VIBROROLLER
A6: 1 | B6: VIBRO | C6: Bomag Smooth Drum Compactor BW211D-40 SL | D6: United Tractors | E6: 2021 | F6: 2021 | G6: 961582391008 | H6: tidak waranty | I6: 138 HP / 103 kW | J6: SD 01 | L6: BRA-SD-1106 | M6: WUR EW | N6: YARD DURI | O6: STANDBY | Q6: PT Chandra Sakti Utama (CSUL) | R6: LUNAS | W6: =IFERROR(IF(E6="","",YEAR(TODAY())-E6),"") -> 5 | X6: VIBROROLLER
A7: 2 | B7: VIBRO | C7: Bomag Smooth Drum Compactor BW211D-40 | D7: United Tractors | E7: 2020 | F7: 2021 | G7: 961582391036 | H7: tidak waranty | I7: 138 HP / 103 kW | J7: SD 02 | L7: SD-00001 | M7: WUR EW | N7: NDD | O7: AKTIF | Q7: PT Chandra Sakti Utama (CSUL) | R7: LUNAS | W7: =IFERROR(IF(E7="","",YEAR(TODAY())-E7),"") -> 6 | X7: VIBROROLLER
A8: 3 | B8: VIBRO | C8: Bomag Smooth Drum Compactor BW211D-40SL | D8: United Tractors | E8: 2021 | F8: 2021 | G8: 961582391145 | H8: tidak waranty | I8: 138 HP / 103 kW | J8: SD 03 | L8: VIBRO BW BRA-06 | M8: - | N8: YARD DURI | O8: STANDBY | Q8: LEASING MTF | R8: LUNAS | W8: =IFERROR(IF(E8="","",YEAR(TODAY())-E8),"") -> 5 | X8: VIBROROLLER
A9: 4 | B9: VIBRO | C9: Bomag Smooth Drum Compactor BW211D-40 | D9: United Tractors | E9: 2022 | F9: 2022 | G9: 961884301945 | H9: Warranty - 3000 | I9: 138 HP / 103 kW | J9: SD 05 | K9: BAMBANG | L9: SD-00004 | M9: WUR EW | N9: INFIELD | O9: AKTIF | Q9: LEASING MTF | W9: =IFERROR(IF(E9="","",YEAR(TODAY())-E9),"") -> 4 | X9: VIBROROLLER
A10: 5 | B10: VIBRO | C10: Bomag Smooth Drum BW211D-40 | D10: United Tractors | E10: 2022 | F10: 2022 | G10: 961884302060 | H10: Warranty - 3000 | I10: 138 HP / 103 kW | J10: SD 06 | K10: ROHIN | L10: SD-41005 | M10: RWI | N10: INTAN (Penasa) | O10: AKTIF | Q10: LEASING MTF | W10: =IFERROR(IF(E10="","",YEAR(TODAY())-E10),"") -> 4 | X10: VIBROROLLER
A11: 6 | B11: VIBRO | C11: Bomag Pad Foot Compactor BW211D-40 | D11: United Tractors | E11: 2022 | F11: 2022 | G11: 961884301016 | H11: tidak waranty | I11: 138 HP / 103 kW | J11: PF 01 | L11: VIBRO BW BRA-02 | M11: KENDARI | N11: BAHODOPI | O11: STANDBY | Q11: PT Chandra Sakti Utama (CSUL) | R11: LUNAS | W11: =IFERROR(IF(E11="","",YEAR(TODAY())-E11),"") -> 4 | X11: VIBROROLLER
A12: 7 | B12: VIBRO | C12: Bomag Pad Foot Compactor BW211D-40 | D12: United Tractors | E12: 2022 | F12: 2022 | G12: 961884301614 | H12: Warranty - 3000 | I12: 138 HP / 103 kW | J12: PF 02 | K12: YOPI | L12: PF-00004 | M12: WUR EW | N12: NDD | O12: AKTIF | Q12: LEASING SANF | W12: =IFERROR(IF(E12="","",YEAR(TODAY())-E12),"") -> 4 | X12: VIBROROLLER
A13: 8 | B13: VIBRO | C13: Bomag Pad Foot Compactor BW211D-40SL | D13: United Tractors | E13: 2022 | F13: 2022 | G13: 961582391152 | H13: tidak waranty | I13: 138 HP / 103 kW | J13: PF 03 | K13: JORDAN | L13: PF-1103 | M13: WUR EW | N13: CUCUT/CENTRAL | O13: AKTIF | Q13: LEASING BUANA | W13: =IFERROR(IF(E13="","",YEAR(TODAY())-E13),"") -> 4 | X13: VIBROROLLER
A14: 9 | B14: VIBRO | C14: CAT Smoothdrum CS10GC | D14: Trakindo | E14: 2022 | F14: 2022 | G14: T8F00361 | H14: tidak waranty | I14: 111 HP / 83 kW | J14: PF 04 | L14: SD-4102 | M14: RWI | N14: INTAN (Penasa) | O14: AKTIF | Q14: JAKARTA | R14: LUNAS | W14: =IFERROR(IF(E14="","",YEAR(TODAY())-E14),"") -> 4 | X14: VIBROROLLER
A15: 10 | B15: VIBRO | C15: Bomag Smooth Drum Compactor BW211D-40SL | D15: United Tractors | E15: 2022 | F15: 2022 | G15: 961582391103 | H15: tidak waranty | I15: 138 HP / 103 kW | J15: SD 07 | L15: VIBRO BW BRA-07 | M15: - | N15: YARD DURI | O15: STANDBY | Q15: LEASING BUANA | W15: =IFERROR(IF(E15="","",YEAR(TODAY())-E15),"") -> 4 | X15: VIBROROLLER
A16: 11 | B16: VIBRO | C16: Bomag Smooth Drum Compactor BW211D-40SL | D16: United Tractors | E16: 2024 | F16: 2024 | G16: 961582391660 | H16: voucher parts ut | I16: 138 HP / 103 kW | J16: SD 08 | L16: SD-41004 | M16: RWI | N16: YARD DURI | O16: STANDBY | Q16: LEASING MTF | W16: =IFERROR(IF(E16="","",YEAR(TODAY())-E16),"") -> 2 | X16: VIBROROLLER
A17: 12 | B17: VIBRO | C17: Bomag Smooth Drum Compactor BW211D-40SL | D17: United Tractors | E17: 2024 | F17: 2024 | G17: 961582391661 | H17: voucher parts ut | I17: 138 HP / 103 kW | J17: SD 09 | K17: ISMAIL | L17: SD-00005 | M17: WUR EW | N17: MESO | O17: AKTIF | Q17: LEASING MTF | W17: =IFERROR(IF(E17="","",YEAR(TODAY())-E17),"") -> 2 | X17: VIBROROLLER
A18: 13 | B18: VIBRO | C18: Bomag Pad Foot Compactor BW211D-40SL (WITH SOIL) | D18: United Tractors | E18: 2024 | F18: 2024 | G18: 961582391717 | H18: voucher parts ut | I18: 138 HP / 103 kW | J18: PF 05 | K18: HENDI | L18: PF-00001 | M18: WUR EW | N18: NDD | O18: AKTIF | W18: =IFERROR(IF(E18="","",YEAR(TODAY())-E18),"") -> 2 | X18: VIBROROLLER
A19: 14 | B19: VIBRO | C19: Bomag Pad Foot Compactor BW211D-40SL (WITH SOIL) | D19: United Tractors | E19: 2024 | F19: 2024 | G19: 961582391718 | H19: voucher parts ut | I19: 138 HP / 103 kW | J19: PF 06 | K19: SUPRIADI | L19: PF-00002 | M19: WUR EW | N19: NDD | O19: AKTIF | W19: =IFERROR(IF(E19="","",YEAR(TODAY())-E19),"") -> 2 | X19: VIBROROLLER
A20: 15 | B20: VIBRO | C20: Bomag Smooth Drum Compactor BW211D-40 SL | D20: United Tractors | E20: 2024 | F20: 2024 | G20: 961582391716 | H20: voucher parts ut | I20: 138 HP / 103 kW | J20: SD 10 | K20: HASBI | L20: SD-00002 | M20: WUR EW | N20: NDD | O20: AKTIF | W20: =IFERROR(IF(E20="","",YEAR(TODAY())-E20),"") -> 2 | X20: VIBROROLLER
A21: 16 | B21: VIBRO | C21: CAT Pad Foot CS10GC | D21: Trakindo | E21: 2025 | F21: 2025 | G21: T8F03605 | H21: Warranty 4000 | I21: 111 HP / 83 kW | J21: SD 11 | L21: VBBRA-011 | M21: ADERA | N21: ADERA | O21: AKTIF | W21: =IFERROR(IF(E21="","",YEAR(TODAY())-E21),"") -> 1 | X21: VIBROROLLER
A22: 17 | B22: VIBRO | C22: CAT Pad Foot CS10GC | D22: Trakindo | E22: 2025 | F22: 2025 | G22: T8F03606 | H22: Warranty 4000 | I22: 111 HP / 83 kW | J22: SD 12 | L22: VBBRA-012 | M22: ADERA | N22: ADERA | O22: AKTIF | W22: =IFERROR(IF(E22="","",YEAR(TODAY())-E22),"") -> 1 | X22: VIBROROLLER
A23: 18 | B23: VIBRO | C23: SAKAI Sheep Foot Compactor SV700TF | D23: Star Wagon | E23: 2025 | F23: 2025 | G23: VSV19T-10259 | H23: Warranty 2000 | I23: 18 TON / 166 HP / 124 kW | J23: PF07 | K23: WILTON | L23: PF-41001 | M23: RWI | N23: BP. HELI (Bekasap) | O23: AKTIF | W23: =IFERROR(IF(E23="","",YEAR(TODAY())-E23),"") -> 1 | X23: VIBROROLLER
A24: 19 | B24: VIBRO | C24: Sheep Foot XCMG XS250PD | D24: Sacindo | E24: 2026 | F24: 2026 | G24: XUG02051KSJE02502 | I24: 20 TON | J24: PF08 | K24: ADE JOANDA | L24: PF-41002 | M24: RWI | N24: CENTRAL | O24: AKTIF | W24: =IFERROR(IF(E24="","",YEAR(TODAY())-E24),"") -> 0 | X24: VIBROROLLER
A25: 20 | B25: VIBRO | C25: Sheep Foot XCMG X113E PD | D25: Sacindo | E25: 2026 | F25: 2026 | G25: XUG01131PSJE06060 | I25: 11 TON | J25: PF09 | K25: M. ARIF | L25: SD-41003 | M25: RWI | N25: CENTRAL | O25: AKTIF | W25: =IFERROR(IF(E25="","",YEAR(TODAY())-E25),"") -> 0 | X25: VIBROROLLER
A26: 21 | C26: HAMM Vibro Pad Foot Compactor HC208D | D26: Gaya Makmur Tractors | E26: 2026 | F26: 2026 | G26: HC208D | I26: 20 TON | J26: PF10 | K26: LOEWINSYAH | L26: PF-41003 | M26: RWI | N26: SIMPANG HELI | O26: AKTIF | W26: =IFERROR(IF(E26="","",YEAR(TODAY())-E26),"") -> 0 | X26: VIBROROLLER
A27: B | C27: MOTOR GRADER
A28: 1 | B28: MOTOR GRADER | C28: MOTOR GRADER CAT 120 K | D28: Trakindo | E28: 2013 | F28: 2013 | G28: SZN01229 | H28: tidak waranty | I28: 120 HP | J28: GR 1 | K28: HERMAN | L28: MG-00005 | M28: WUR EW | N28: B.PIT HARAPAN BARU | O28: AKTIF | Q28: PEKANBARU | R28: LUNAS | W28: =IFERROR(IF(E28="","",YEAR(TODAY())-E28),"") -> 13 | X28: MOTOR GRADER
A29: 2 | B29: MOTOR GRADER | C29: MOTOR GRADER KOMATSU GD535-5 | D29: United Tractors | E29: 2024 | F29: 2024 | G29: 2066 | H29: voucher parts ut | I29: 145 HP | J29: GR 2 | L29: MG BRA-002 | M29: ADERA | N29: ADERA | O29: AKTIF | Q29: LEASING MTF | W29: =IFERROR(IF(E29="","",YEAR(TODAY())-E29),"") -> 2 | X29: MOTOR GRADER
A30: 3 | B30: MOTOR GRADER | C30: MOTOR GRADER KOMATSU GD535-5 | D30: United Tractors | E30: 2019 | F30: 2019 | G30: 1372 | H30: tidak waranty | I30: 145 HP | J30: GR3 | K30: BAYU | L30: MG-41002 | M30: RWI | N30: INTAN (Penasa) | O30: AKTIF | Q30: BUANA | R30: LUNAS | W30: =IFERROR(IF(E30="","",YEAR(TODAY())-E30),"") -> 7 | X30: MOTOR GRADER
A31: 4 | B31: MOTOR GRADER | C31: MOTOR GRADER KOMATSU GD535-5 | D31: United Tractors | E31: 2025 | F31: 2025 | G31: 2259 | H31: tidak waranty | I31: 145 HP | J31: GR4 | L31: MG BRA-004 | M31: ADERA | N31: ADERA | O31: AKTIF | W31: =IFERROR(IF(E31="","",YEAR(TODAY())-E31),"") -> 1 | X31: MOTOR GRADER
A32: 5 | B32: MOTOR GRADER | C32: MOTOR GRADER XCMG GR135 MAX | D32: Gaya Makmur Putra | E32: 2024 | F32: 2024 | G32: PRDB00108 | I32: 150 HP | J32: GR5 | K32: JUNI HARDI | L32: MG-00004 | M32: WUR EW | N32: NDD | O32: AKTIF | W32: =IFERROR(IF(E32="","",YEAR(TODAY())-E32),"") -> 2 | X32: MOTOR GRADER
A33: 6 | B33: MOTOR GRADER | C33: MOTOR GRADER KOMATSU GD535-5 | D33: United Tractors | E33: 2026 | F33: 2026 | G33: 1319 | H33: tidak waranty | I33: 145 HP | J33: GR6 | L33: MG BRA-06 | M33: KENDARI | N33: BAHODOPI | O33: AKTIF | W33: =IFERROR(IF(E33="","",YEAR(TODAY())-E33),"") -> 0 | X33: MOTOR GRADER
A34: 7 | C34: MOTOR GRADER KOMATSU GD535-5 | D34: United Tractors | E34: 2019 | F34: 2019 | G34: 1376 | I34: 145 HP | J34: GR7 | K34: PERNANDA | L34: BRR-MG-4105 | M34: RWI | N34: PENASA | O34: AKTIF | Q34: JAKARTA | R34: LUNAS | W34: =IFERROR(IF(E34="","",YEAR(TODAY())-E34),"") -> 7 | X34: MOTOR GRADER
A35: 8 | C35: MOTOR GRADER KOMATSU GD535-5 | D35: United Tractors | E35: 2017 | F35: 2017 | G35: 1017 | I35: 145 HP | J35: GR8 | K35: SYAHWARI | L35: MG-41006 | M35: RWI | N35: BP. HELI (Bekasap) | O35: AKTIF | Q35: JAKARTA | R35: LUNAS | W35: =IFERROR(IF(E35="","",YEAR(TODAY())-E35),"") -> 9 | X35: MOTOR GRADER
A36: 9 | C36: MOTOR GRADER KOMATSU GD535-5 | D36: - | E36: 2018 | F36: 2018 | G36: 1135 | I36: 145 HP | J36: GR9 | L36: - | M36: - | N36: YARD DURI | O36: STANDBY | W36: =IFERROR(IF(E36="","",YEAR(TODAY())-E36),"") -> 8 | X36: MOTOR GRADER
A37: C | C37: BULLDOZER
A38: 1 | B38: BULLDOZER | C38: Bulldozer Caterpillar D6G | D38: trakindo | E38: 2006 | F38: 2006 | G38: P6G00163 | H38: tidak waranty | I38: 160 HP | J38: Dozer 01 | L38: BRA-01 | M38: WS ADERA | N38: WS ADERA | O38: STANDBY | Q38: PEKANBARU | R38: LUNAS | W38: =IFERROR(IF(E38="","",YEAR(TODAY())-E38),"") -> 20 | X38: BULLDOZER
A39: 2 | B39: BULLDOZER | C39: Bulldozer Caterpillar D6G 2XL | D39: trakindo | E39: 2012 | F39: 2012 | G39: P6G01656 | H39: tidak waranty | I39: 160 HP | J39: Dozer 03 | L39: DZ-00002 | M39: YARD DURI | N39: YARD DURI | O39: STANDBY | Q39: JAKARTA | R39: LUNAS | W39: =IFERROR(IF(E39="","",YEAR(TODAY())-E39),"") -> 14 | X39: BULLDOZER
A40: 3 | B40: BULLDOZER | C40: Bulldozer Komatsu D85ESS-2 | D40: KOMATSU | E40: 2012 | F40: 2012 | G40: J16298 | H40: tidak waranty | I40: 215 HP | J40: Dozer 04 | L40: DZ-00005 | M40: YARD DURI | N40: YARD DURI | O40: STANDBY | Q40: JAKARTA | R40: LUNAS | W40: =IFERROR(IF(E40="","",YEAR(TODAY())-E40),"") -> 14 | X40: BULLDOZER
A41: 4 | B41: BULLDOZER | C41: Bulldozer Caterpillar D6R | D41: Trakindo | E41: 2011 | F41: 2011 | G41: S6X00348 | H41: tidak waranty | I41: 200 HP | J41: Dozer 06 | L41: BRA-01 | M41: KENDARI | N41: MALILI | O41: STANDBY | Q41: PEKANBARU | R41: LUNAS | W41: =IFERROR(IF(E41="","",YEAR(TODAY())-E41),"") -> 15 | X41: BULLDOZER
A42: 5 | B42: BULLDOZER | C42: Bulldozer Caterpillar D6G 2XL | D42: Trakindo | E42: 2012 | F42: 2012 | G42: P6G01529 | H42: tidak waranty | I42: 160 HP | J42: Dozer 05 | L42: DZ-00003 | M42: KENDARI | N42: MALILI | O42: STANDBY | Q42: JAKARTA | R42: LUNAS | W42: =IFERROR(IF(E42="","",YEAR(TODAY())-E42),"") -> 14 | X42: BULLDOZER
...

Sheet Sheet35
A2: REKAP HEAVY EQUIPMENT BRA
A3: No | B3: Nama Asset | C3: Tahun | D3: SN/ Plat Kendaraan | E3: Kode Unit | F3: Nomor Lambung Aktual | G3: PROJECT | H3: STATUS/sisa cicilan | I3: CICILAN/BULAN | J3: Total Sisa Cicilan | K3: DEPRESIASI | L3: RATA2 PERBAIKAN /BULAN
A4: 1 | B4: Bomag Smooth Drum Compactor BW211D-40 SL | C4: 2020 | D4: 961582391008 | E4: SD 01 | F4: VIBRO BW BRA-01 | G4: KENDARI | H4: LUNAS | K4: 551604167 | L4: 3459238
A5: 2 | B5: Bomag Smooth Drum Compactor BW211D-40SL | C5: 2021 | D5: 961582391145 | E5: SD 03 | F5: VIBRO BW BRA-03 | G5: KENDARI | H5: LUNAS | K5: 452093750 | L5: 3320349
A6: 3 | B6: Bomag Pad Foot Compactor BW211D-40 | C6: 2022 | D6: 961884301016 | E6: PF 01 | F6: VIBRO BW BRA-02 | G6: KENDARI | H6: LUNAS | K6: 729322917 | L6: 2103682
A7: 4 | B7: Bomag Smooth Drum Compactor BW211D-40SL | C7: 2022 | D7: 961582391103 | E7: SD 07 | F7: VIBRO BW BRA-07 | G7: KENDARI | H7: 14/36 | I7: 22343000 | J7: =I7*14 -> 312802000 | K7: 169531250 | L7: 2103682
A8: 5 | B8: Bulldozer Caterpillar D6G 2XL | C8: 2012 | D8: P6G01529 | E8: Dozer 05 | F8: DZ-00003 | G8: KENDARI | H8: LUNAS | K8: 389062500 | L8: 4278587
A9: 6 | B9: Excavator Caterpillar 320 GC | C9: 2022 | D9: DKJ40199 | E9: Exca 10 | F9: BRA-10 | G9: KENDARI | H9: LUNAS | K9: 770952813 | L9: 1242337
A10: 7 | B10: Excavator Caterpillar 320 GC | C10: 2022 | D10: DKJ40200 | E10: Exca 11 | F10: BRA-11 | G10: KENDARI | H10: LUNAS | K10: 770952813 | L10: 815972
A11: 8 | B11: Excavator Caterpillar 320 GC | C11: 2022 | D11: DKJ40263 | E11: Exca 14 | F11: BRA-14 | G11: KENDARI | H11: LUNAS | K11: 713868750 | L11: 1515221
A12: 9 | B12: Excavator Caterpillar 320 GC | C12: 2022 | D12: DKJ40294 | E12: Exca 15 | F12: BRA-15 | G12: KENDARI | H12: LUNAS | K12: 713868750 | L12: 1584695
A13: 10 | B13: Excavator PC 210-10M0/P1 | C13: 2023 | D13: C00637 | E13: Exca 26 | F13: BRA-26 | G13: KENDARI | H13: 23/36 | I13: 26545103 | J13: =I13*23 -> 610537369 | K13: 145687500 | L13: 1035426
A14: 11 | B14: Bulldozer Caterpillar D6R | C14: 2011 | D14: S6X00348 | E14: Dozer 06 | F14: BRA-01 | G14: KENDARI | H14: LUNAS | K14: 262500000 | L14: 22924720
A18: No | B18: Nama Asset | C18: Tahun | D18: SN/ Plat Kendaraan | E18: Merk | F18: Lokasi | G18: Kapasitas
A19: 1 | B19: Bomag Smooth Drum BW211D-40 | C19: 2022 | D19: 961884302060 | E19: BOMAG | F19: YARD DURI | G19: 138 HP / 103 kW
A20: 2 | B20: Bomag Pad Foot Compactor BW211D-40SL | C20: 2022 | D20: 961582391152 | E20: BOMAG | F20: YARD DURI | G20: 138 HP / 103 kW
A21: 3 | B21: Bomag Smooth Drum Compactor BW211D-40SL | C21: 2024 | D21: 961582391660 | E21: BOMAG | F21: YARD DURI | G21: 138 HP / 103 kW
A22: 4 | B22: Excavator CAT 320 GX new | C22: 2022 | D22: SYW01364 | E22: CATERPILLAR | F22: YARD DURI | G22: 138 HP / 0.90 M3
A23: 5 | B23: Excavator Komatsu PC 200-10 MOCE | C23: 2022 | D23: DBCHO380 | E23: KOMATSU | F23: YARD DURI | G23: 138 HP / 1.0 M3
A24: 6 | B24: Excavator Caterpillar 305.5E2 | C24: 2023 | D24: WE217079 | E24: CATERPILLAR | F24: YARD DURI | G24: 41 HP / 0.22 M3
A25: 7 | B25: Excavator Caterpillar 305.5E2 | C25: 2023 | D25: WE217080 | E25: CATERPILLAR | F25: YARD DURI | G25: 41 HP / 0.22 M3
A26: 8 | B26: Excavator Caterpillar 305.5E2 | C26: 2023 | D26: WE217081 | E26: CATERPILLAR | F26: YARD DURI | G26: 41 HP / 0.22 M3
A27: 9 | B27: Crawler Crane Zoomlion ZCC600V | C27: 2023 | D27: ZCC60-0199 | E27: ZOOMLION | F27: YARD DURI | G27: 60 TON
A28: 10 | B28: Dump Truck QUESTER | C28: 2019 | D28: Z 9109 AB | E28: QUESTER | F28: YARD DURI | G28: 24 M3
A29: 11 | B29: Dump Truck HINO RANGER-FM 260 JD | C29: 2019 | D29: DT 9782 LE/ DT 8669 KE | E29: HINO | F29: YARD DURI | G29: 24 M3
A30: 12 | B30: Dumptruck Isuzu NMR 81 | C30: 2023 | D30: B9097ZYT | E30: ISUZU | F30: YARD DURI | G30: 8 M3
A31: 13 | B31: Dumptruck Isuzu NMR 81 | C31: 2023 | D31: B9098ZYT | E31: ISUZU | F31: YARD DURI | G31: 8 M3

Sheet DATA UNIT A2B DI YARD KM 12
B4: Nama Asset | C4: Dealer | D4: Tahun | E4: Serial Number | F4: Kapasitas | G4: Kode Unit | H4: Nomor Lambung Aktual | I4: PROJECT | J4: LOKASI | K4: TARGET PENYELESAIAN | L4: KETERANGAN
B5: Bomag Smooth Drum BW211D-40 | C5: United Tractors | D5: 2022 | E5: 961884302060 | F5: 138 HP / 103 kW | G5: SD 06 | H5: VIBRO BW BRA-06 | I5: RWI | J5: YAR DURI | L5: STATUS READY STAND BY
B6: Bomag Pad Foot Compactor BW211D-40SL | C6: United Tractors | D6: 2022 | E6: 961582391152 | F6: 138 HP / 103 kW | G6: PF 03 | H6: PF-00003 | I6: WUR EW | J6: YAR DURI | L6: STATUS READY STAND BY
B7: Bomag Smooth Drum Compactor BW211D-40SL | C7: United Tractors | D7: 2024 | E7: 961582391660 | F7: 138 HP / 103 kW | G7: SD 08 | H7: VIBRO BW BRA-08 | I7: RWI | J7: YAR DURI | L7: STATUS READY STAND BY
B8: Bulldozer Caterpillar D6G 2XL | C8: trakindo | D8: 2012 | E8: P6G01656 | F8: 160 HP | G8: Dozer 03 | H8: DZ-00002 | I8: YARD DURI | J8: YAR DURI | K8: ESTIMASI INSPEKSI TANGGAL 8 SEP 2026 | L8: STATUS READY WAITING INSPEKSI PAK ERI CEM
B9: Bulldozer Komatsu D85ESS-2 | C9: KOMATSU | D9: 2012 | E9: J16298 | F9: 215 HP | G9: Dozer 04 | H9: DZ-00005 | I9: YARD DURI | J9: YAR DURI | L9: STATUS READY
B10: Excavator PC 210-10M0/P1 | C10: United Tractors | D10: 2020 | E10: C01530 | F10: 165 HP / 1.2 M3 | G10: Exca 02 | H10: EXC-00013 | I10: KELMI/LABAN | J10: YAR DURI | K10: ESTIMASI READY TANGGAL 12 SEP 2026 | L10: RFU ,PROSES PENGECATAN,PLAN PERGANTIAN OLI HYDRAULIC
B11: Excavator Caterpillar 305.5E2 | C11: Trakindo | D11: 2023 | E11: WE217079 | F11: 41 HP / 0.22 M3 | G11: Exca 16 | H11: HE-6.004 | I11: YARD DURI | J11: YAR DURI | L11: UNIT READY STAND BY,SENSOR TRAVEL BELUM MODIFIKASI
B12: Excavator Caterpillar 305.5E2 | C12: Trakindo | D12: 2023 | E12: WE217080 | F12: 41 HP / 0.22 M3 | G12: Exca 17 | H12: HE-6.001 | I12: YARD DURI | J12: YAR DURI | K12: ESTIMASI READY 07 /10/2026 | L12: PART INDENT TRAKINDO,MASIH DI CARIKAN PERSAMAAN ORI OLEH PAK ERI GUSWAN
B13: Excavator Caterpillar 305.5E2 | C13: Trakindo | D13: 2023 | E13: WE217081 | F13: 41 HP / 0.22 M3 | G13: Exca 18 | H13: HE-6.006 | I13: YARD DURI | J13: YAR DURI | L13: UNIT READY STAND BY,SEDANG PEMASANGAN GPS
B14: Excavator PC 200-10 MO | C14: United Tractors | D14: 2022 | E14: C51502 | F14: 138 HP / 1.0 M3 | G14: Exca 20 | H14: EXC-00007 | I14: WUR EW | J14: YAR DURI
B15: Excavator PC 200-10 MO | C15: United Tractors | D15: 2024 | E15: DBCH1784 | F15: 138 HP / 1.0 M3 | G15: Exca 23 | H15: EXC-41001 | I15: KELMI/LABAN | J15: YAR DURI
B16: Wheel Loader SEM 655D (Pallet Fork) | C16: Tri Swardana Utama | D16: 2025 | E16: S5512759 | F16: 162 kW / 217 HP | G16: WL 02 | H16: WL-31001 | I16: MATTING BOARD | J16: YAR DURI | L16: UNIT READY STAND BY BEROPERASI DI YARD
B17: Crawler Crane Zoomlion ZCC600V | C17: Total Crane | D17: 2024 | E17: ZCC60-0199 | F17: 60 TON | G17: CC-01 | H17: CC-00001 | I17: YARD DURI | J17: YAR DURI | K17: ESTIMASI 14 SEP 2026 | L17: UNIT BREAKDOWN ,WAITING MEKANIK UNIQUIP EQUIPMENT INDONESIA
B18: EXCAVATOR PC 210-10 MO | C18: United Tractors | D18: 2020 | E18: C01531 | F18: 165 HP/1.2 M3 | G18: EXCA-1108 | H18: BRA-EXC-1108 | I18: WUR EW | J18: YARD DURI | L18: READY STAND BY,PLAN NEXT PAINTING
B19: EXCAVATOR

Sheet List rekap  dokumen
A2: REKAP HEAVY EQUIPMENT DAN VEHICLE PT BINA REKAYASA ANUGRAH
A4: No | C4: Nama Asset | D4: Dealer | E4: SerialNUmber | F4: Tahun | G4: INVOICE | H4: SILO | I4: PAJAK | J4: SNTK | K4: KIR | L4: BPKB | M4: FOTO 4 SISI | N4: KETERANGAN
A5: A | B5: JENIS ALAT | C5: VIBROROLLER
A6: 1 | B6: VIBRO | C6: Bomag Smooth Drum Compactor BW211D-40 SL | D6: United Tractors | E6: 961582391008 | F6: 2020 | G6: FALSE | H6: FALSE | I6: FALSE | J6: FALSE | K6: FALSE | L6: FALSE | M6: FALSE
A7: 2 | B7: VIBRO | C7: Bomag Smooth Drum Compactor BW211D-40 | D7: United Tractors | E7: 961582391036 | F7: 2020 | G7: FALSE | H7: FALSE | I7: FALSE | J7: FALSE | K7: FALSE | L7: FALSE | M7: FALSE
A8: 3 | B8: VIBRO | C8: Bomag Smooth Drum Compactor BW211D-40SL | D8: United Tractors | E8: 961582391145 | F8: 2021 | G8: FALSE | H8: FALSE | I8: FALSE | J8: FALSE | K8: FALSE | L8: FALSE | M8: FALSE
A9: 4 | B9: VIBRO | C9: Bomag Smooth Drum Compactor BW211D-40 | D9: United Tractors | E9: 961884301945 | F9: 2022 | G9: FALSE | H9: FALSE | I9: FALSE | J9: FALSE | K9: FALSE | L9: FALSE | M9: FALSE
A10: 5 | B10: VIBRO | C10: Bomag Smooth Drum BW211D-40 | D10: United Tractors | E10: 961884302060 | F10: 2022 | G10: FALSE | H10: FALSE | I10: FALSE | J10: FALSE | K10: FALSE | L10: FALSE | M10: FALSE
A11: 6 | B11: VIBRO | C11: Bomag Pad Foot Compactor BW211D-40 | D11: United Tractors | E11: 961884301016 | F11: 2022 | G11: FALSE | H11: FALSE | I11: FALSE | J11: FALSE | K11: FALSE | L11: FALSE | M11: FALSE
A12: 7 | B12: VIBRO | C12: Bomag Pad Foot Compactor BW211D-40 | D12: United Tractors | E12: 961884301614 | F12: 2022 | G12: FALSE | H12: FALSE | I12: FALSE | J12: FALSE | K12: FALSE | L12: FALSE | M12: FALSE
A13: 8 | B13: VIBRO | C13: Bomag Pad Foot Compactor BW211D-40SL | D13: United Tractors | E13: 961582391152 | F13: 2022 | G13: FALSE | H13: FALSE | I13: FALSE | J13: FALSE | K13: FALSE | L13: FALSE | M13: FALSE
A14: 9 | B14: VIBRO | C14: CAT Smoothdrum CS10GC | D14: Trakindo | E14: T8F00361 | F14: 2022 | G14: FALSE | H14: FALSE | I14: FALSE | J14: FALSE | K14: FALSE | L14: FALSE | M14: FALSE
A15: 10 | B15: VIBRO | C15: Bomag Smooth Drum Compactor BW211D-40SL | D15: United Tractors | E15: 961582391103 | F15: 2022 | G15: FALSE | H15: FALSE | I15: FALSE | J15: FALSE | K15: FALSE | L15: FALSE | M15: FALSE
A16: 11 | B16: VIBRO | C16: Bomag Smooth Drum Compactor BW211D-40SL | D16: United Tractors | E16: 961582391660 | F16: 2024 | G16: FALSE | H16: FALSE | I16: FALSE | J16: FALSE | K16: FALSE | L16: FALSE | M16: FALSE
A17: 12 | B17: VIBRO | C17: Bomag Smooth Drum Compactor BW211D-40SL | D17: United Tractors | E17: 961582391661 | F17: 2024 | G17: FALSE | H17: FALSE | I17: FALSE | J17: FALSE | K17: FALSE | L17: FALSE | M17: FALSE
A18: 13 | B18: VIBRO | C18: Bomag Pad Foot Compactor BW211D-40SL (WITH SOIL) | D18: United Tractors | E18: 961582391717 | F18: 2024 | G18: FALSE | H18: FALSE | I18: FALSE | J18: FALSE | K18: FALSE | L18: FALSE | M18: FALSE
A19: 14 | B19: VIBRO | C19: Bomag Pad Foot Compactor BW211D-40SL (WITH SOIL) | D19: United Tractors | E19: 961582391718 | F19: 2024 | G19: FALSE | H19: FALSE | I19: FALSE | J19: FALSE | K19: FALSE | L19: FALSE | M19: FALSE
A20: 15 | B20: VIBRO | C20: Bomag Smooth Drum Compactor BW211D-40 SL | D20: United Tractors | E20: 961582391716 | F20: 2024 | G20: FALSE | H20: FALSE | I20: FALSE | J20: FALSE | K20: FALSE | L20: FALSE | M20: FALSE
A21: 16 | B21: VIBRO | C21: CAT Pad Foot CS10GC | D21: Trakindo | E21: T8F03605 | F21: 2025 | G21: FALSE | H21: FALSE | I21: FALSE | J21: FALSE | K21: FALSE | L21: FALSE | M21: FALSE
A22: 17 | B22: VIBRO | C22: CAT Pad Foot CS10GC | D22: Trakindo | E22: T8F03606 | F22: 2025 | G22: FALSE | H22: FALSE | I22: FALSE | J22: FALSE | K22: FALSE | L22: FALSE | M22: FALSE
A23: 18 | B23: VIBRO | C23: SAKAI Sheep Foot Compactor SV700TF | D23: Star Wagon | E23: VSV19T-10259 | F23: 2025 | G23: FALSE | H23: FALSE | I23: FALSE | J23: FALSE | K23: FALSE | L23: FALSE | M23: FALSE
A24: 19 | B24: VIBRO | C24: Sheep Foot XCMG XS250PD | D24: Sacindo | E24: XUG02051KSJE02502 | F24: 2026 | G24: FALSE | H24: FALSE | I24: FALSE | J24: FALSE | K24: FALSE | L24: FALSE | M24: FALSE
A25: 20 | B25: VIBRO | C25: Sheep Foot XCMG X113E PD | D25: Sacindo | E25: XUG01131PSJE06060 | F25: 2026 | G25: FALSE | H25: FALSE | I25: FALSE | J25: FALSE | K25: FALSE | L25: FALSE | M25: FALSE
A26: B | C26: MOTOR GRADER
A27: 1 | B27: MOTOR GRADER | C27: MOTOR GRADER CAT 120 K | D27: Trakindo | E27: SZN01229 | F27: 2013 | G27: FALSE | H27: FALSE | I27: FALSE | J27: FALSE | K27: FALSE | L27: FALSE | M27: FALSE
A28: 2 | B28: MOTOR GRADER | C28: MOTOR GRADER KOMATSU GD535-5 | D28: United Tractors | E28: 2066 | F28: 2024 | G28: FALSE | H28: FALSE | I28: FALSE | J28: FALSE | K28: FALSE | L28: FALSE | M28: FALSE
A29: 3 | B29: MOTOR GRADER | C29: MOTOR GRADER KOMATSU GD535-5 | D29: United Tractors | E29: 1372 | F29: 2019 | G29: FALSE | H29: FALSE | I29: FALSE | J29: FALSE | K29: FALSE | L29: FALSE | M29: FALSE
A30: 4 | B30: MOTOR GRADER | C30: MOTOR GRADER KOMATSU GD535-5 | D30: United Tractors | E30: 2259 | F30: 2025 | G30: FALSE | H30: FALSE | I30: FALSE | J30: FALSE | K30: FALSE | L30: FALSE | M30: FALSE
A31: 5 | B31: MOTOR GRADER | C31: MOTOR GRADER XCMG GR135 MAX | D31: Gaya Makmur Putra | E31: PRDB00108 | F31: 2024 | G31: FALSE | H31: FALSE | I31: FALSE | J31: FALSE | K31: FALSE | L31: FALSE | M31: FALSE
A32: 6 | B32: MOTOR GRADER | C32: MOTOR GRADER KOMATSU GD535-5 | D32: United Tractors | E32: 1319 | F32: 2026 | G32: FALSE | H32: FALSE | I32: FALSE | J32: FALSE | K32: FALSE | L32: FALSE | M32: FALSE
A33: 7 | C33: MOTOR GRADER KOMATSU GD535-5 | G33: FALSE | H33: FALSE | I33: FALSE | J33: FALSE | K33: FALSE | L33: FALSE | M33: FALSE
A34: 8 | C34: MOTOR GRADER KOMATSU GD535-5 | G34: FALSE | H34: FALSE | I34: FALSE | J34: FALSE | K34: FALSE | L34: FALSE | M34: FALSE
A35: C | C35: BULLDOZER
A36: 1 | B36: BULLDOZER | C36: Bulldozer Caterpillar D6G | D36: trakindo | E36: P6G00163 | F36: 2006 | G36: FALSE | H36: FALSE | I36: FALSE | J36: FALSE | K36: FALSE | L36: FALSE | M36: FALSE
A37: 2 | B37: BULLDOZER | C37: Bulldozer Caterpillar D6G 2XL | D37: trakindo | E37: P6G01656 | F37: 2012 | G37: FALSE | H37: FALSE | I37: FALSE | J37: FALSE | K37: FALSE | L37: FALSE | M37: FALSE
A38: 3 | B38: BULLDOZER | C38: Bulldozer Komatsu D85ESS-2 | D38: KOMATSU | E38: J16298 | F38: 2012 | G38: FALSE | H38: FALSE | I38: FALSE | J38: FALSE | K38: FALSE | L38: FALSE | M38: FALSE
A39: 4 | B39: BULLDOZER | C39: Bulldozer Caterpillar D6R | D39: Trakindo | E39: S6X00348 | F39: 2011 | G39: FALSE | H39: FALSE | I39: FALSE | J39: FALSE | K39: FALSE | L39: FALSE | M39: FALSE
A40: 5 | B40: BULLDOZER | C40: Bulldozer Caterpillar D6G 2XL | D40: Trakindo | E40: P6G01529 | F40: 2012 | G40: FALSE | H40: FALSE | I40: FALSE | J40: FALSE | K40: FALSE | L40: FALSE | M40: FALSE
A41: 6 | B41: BULLDOZER | C41: Bulldozer Caterpillar D7G2 | D41: Trakindo | E41: 7MB05410 | F41: 2010 | G41: FALSE | H41: FALSE | I41: FALSE | J41: FALSE | K41: FALSE | L41: FALSE | M41: FALSE
A42: 7 | B42: BULLDOZER | C42: Bulldozer Komatsu D85ESS-2 | D42: United Tractors | E42: J21020 | F42: 2024 | G42: FALSE | H42: FALSE | I42: FALSE | J42: FALSE | K42: FALSE | L42: FALSE | M42: FALSE
...

Sheet PROJECT WUR
A2: REKAP HEAVY EQUIPMENT DAN VEHICLE PT BRA PROJECT WUR
A3: No | B3: Nama Asset | C3: Tahun | D3: SN/ Plat Kendaraan | E3: Kapasitas | F3: Kode Unit | G3: Nomor Lambung Aktual | H3: Project | I3: Total Biaya
B4: DUMPTRUCK
A5: 1 | B5: Dump Truck HINO RANGER-FM 280 JD | C5: 2024 | D5: B9107ZYT | E5: 24 M3 | F5: DT 55 | G5: DT-00001 | H5: WUR EW | I5: 2317000
A6: 2 | B6: Dump Truck HINO RANGER-FM 280 JD | C6: 2024 | D6: B9110ZYT | E6: 24 M3 | F6: DT 56 | G6: DT-00002 | H6: WUR EW | I6: 1951000
A7: 3 | B7: Dump Truck HINO RANGER-FM 280 JD | C7: 2024 | D7: B9109ZYT | E7: 24 M3 | F7: DT 57 | G7: DT-00003 | H7: WUR EW | I7: 4950000
A8: 4 | B8: Dump Truck HINO RANGER-FM 280 JD | C8: 2024 | D8: B9112ZYT | E8: 24 M3 | F8: DT 58 | G8: DT-00004 | H8: WUR EW | I8: 342000
A9: 5 | B9: Dump Truck HINO RANGER-FM 280 JD | C9: 2024 | D9: B9113ZYT | E9: 24 M3 | F9: DT 59 | G9: DT-00005 | H9: WUR EW | I9: 9823000
A10: 6 | B10: Dump Truck HINO RANGER-FM 280 JD | C10: 2024 | D10: B9118ZYT | E10: 24 M3 | F10: DT 60 | G10: DT-00006 | H10: WUR EW | I10: 10508000
A11: 7 | B11: Dump Truck HINO RANGER-FM 280 JD | C11: 2024 | D11: B9114ZYT | E11: 24 M3 | F11: DT 61 | G11: DT-00007 | H11: WUR EW | I11: 178000
A12: 8 | B12: Dump Truck HINO RANGER-FM 280 JD | C12: 2024 | D12: B9115ZYT | E12: 24 M3 | F12: DT 62 | G12: DT-00008 | H12: WUR EW | I12: 9077000
A13: 9 | B13: Dump Truck HINO RANGER-FM 280 JD | C13: 2024 | D13: B9116ZYT | E13: 24 M3 | F13: DT 63 | G13: DT-00009 | H13: WUR EW | I13: 1020000
A14: 10 | B14: Dump Truck HINO RANGER-FM 280 JD | C14: 2024 | D14: B9117ZYT | E14: 24 M3 | F14: DT 64 | G14: DT-00010 | H14: WUR EW | I14: 5630000
A15: 11 | B15: Dump Truck HINO RANGER-FM 280 JD | C15: 2024 | D15: B9120ZYT | E15: 24 M3 | F15: DT 65 | G15: DT-00011 | H15: WUR EW | I15: 1633000
A16: 12 | B16: Dump Truck HINO RANGER-FM 280 JD | C16: 2024 | D16: B9121ZYT | E16: 24 M3 | F16: DT 66 | G16: DT-00012 | H16: WUR EW | I16: 1537000
... A59: 55 | B59: Dump Truck HINO RANGER-FM 260 JD | C59: 2017 | D59: B9892PYW | E59: 24 M3 | F59: DT 15 | G59: DT-00056 | H59: WUR EW | I59: 165292139
B60: ALAT BERAT
A61: 1 | B61: Bomag Smooth Drum Compactor BW211D-40 | C61: 2020 | D61: 961582391036 | E61: 138 HP / 103 kW | F61: SD 02 | G61: SD-00001 | H61: WUR EW | I61: 15347150
A62: 2 | B62: Bomag Smooth Drum Compactor BW211D-40 | C62: 2022 | D62: 961884301945 | E62: 138 HP / 103 kW | F62: SD 05 | G62: SD-00004 | H62: WUR EW | I62: 10322400
A63: 3 | B63: Bomag Pad Foot Compactor BW211D-40 | C63: 2022 | D63: 961884301614 | E63: 138 HP / 103 kW | F63: PF 02 | G63: PF-00004 | H63: WUR EW | I63: 2160000
A64: 4 | B64: Bomag Pad Foot Compactor BW211D-40SL (WITH SOIL) | C64: 2024 | D64: 961582391717 | E64: 138 HP / 103 kW | F64: PF 05 | G64: PF-00001 | H64: WUR EW | I64: 12003498
A65: 5 | B65: Bomag Pad Foot Compactor BW211D-40SL (WITH SOIL) | C65: 2024 | D65: 961582391718 | E65: 138 HP / 103 kW | F65: PF 06 | G65: PF-00002 | H65: WUR EW | I65: 1080000
A66: 6 | B66: Bomag Smooth Drum Compactor BW211D-40 SL | C66: 2024 | D66: 961582391716 | E66: 138 HP / 103 kW | F66: SD 10 | G66: SD-00002 | H66: WUR EW | I66: 1080000
A67: 7 | B67: Bomag Smooth Drum Compactor BW211D-40 SL | C67: 2024 | D67: 961582391661 | E67: 138 HP / 103 kW | F67: SD 09 | G67: SD-00005 | H67: WUR EW | I67: 12003498
A68: 8 | B68: MOTOR GRADER CAT 120 K | C68: 2013 | D68: SZN01229 | E68: 120 HP | F68: GR 1 | G68: MG-00005 | H68: WUR EW | I68: 203536765
A69: 9 | B69: MOTOR GRADER XCMG GR135 MAX | C69: 2024 | D69: PRDB00108 | E69: 150 HP | F69: GR5 | G69: MG-00004 | H69: WUR EW | I69: 59574562
A70: 10 | B70: Bulldozer Komatsu D85ESS-2 | C70: 2024 | D70: J21020 | E70: 215 HP | F70: Dozer 08 | G70: DZ-00001 | H70: WUR EW | I70: 4984500
A71: 11 | B71: Bulldozer Zoomlion ZD170G | C71: 2025 | D71: ZLHD116HR1B05388 | E71: 185 HP | F71: Dozer 10 | G71: DZ-00004 | H71: WUR EW | I71: 3950000
A72: 12 | B72: Bulldozer Shantui SD16E | C72: 2025 | D72: CHSD16AEKR1054524 | E72: 130 kW / 174 HP | F72: Dozer 11 | G72: DZ-00006 | H72: WUR EW | I72: 19073000
A73: 13 | B73: Excavator PC 210-10M0/P1 | C73: 2020 | D73: C01531 | E73: 165 HP / 1.2 M3 | F73: Exca 01 | G73: EXC-00008 | H73: WUR EW | I73: 149314500
A74: 14 | B74: Excavator PC 200-10 MO | C74: 2024 | D74: DBCH1801 | E74: 138 HP / 0.90 M3 | F74: Exca 22 | G74: EXC-00012 | H74: WUR EW | I74: 22116000
A75: 15 | B75: Excavator Komatsu PC 200-10 MOCE | C75: 2022 | D75: DBCHO302 | E75: 138 HP / 1.0 M3 | F75: Exca 07 | G75: EXC-00014 | H75: WUR EW | I75: 15843000
A76: 16 | B76: Excavator PC 200-10 MO | C76: 2022 | D76: C51502 | E76: 138 HP / 1.0 M3 | F76: Exca 20 | G76: EXC-00007 | H76: WUR EW | I76: 20555000
A77: 17 | B77: Excavator PC 200-10 MO | C77: 2022 | D77: DBCHO380 | E77: 138 HP / 1.0 M3 | F77: Exca 12 | H77: WUR EW | I77: 18428000
A78: 18 | B78: Excavator PC 200-10 MO | C78: 2022 | D78: C51503 | E78: 138 HP / 1.0 M3 | F78: Exca 21 | G78: EXC-00003 | H78: WUR EW | I78: 14132500
A79: 19 | B79: Excavator PC 200-10 MO | C79: 2024 | D79: DBCH2244 | E79: 138 HP / 1.0 M3 | F79: Exca 24 | G79: EXC-00001 | H79: WUR EW | I79: 265000
A80: 20 | B80: Excavator PC 200-10 MO | C80: 2024 | D80: DBCH2245 | E80: 138 HP / 1.0 M3 | F80: Exca 25 | G80: EXC-00002 | H80: WUR EW | I80: 14449000
A81: 21 | B81: Excavator PC 200-10 MO | C81: 2025 | D81: DBCH2941 | E81: 138 HP / 1.0 M3 | F81: Exca 29 | G81: EXC-00009 | H81: WUR EW | I81: 5820000
A82: 22 | B82: Excavator Komatsu PC 200-10 MOCE | C82: 2022 | D82: DBCH0366 | E82: 138 HP / 1.0 M3 | F82: Exca 13 | G82: EXC-00004 | H82: WUR EW | I82: 8170500
A83: 23 | B83: Crawler Crane XCMG XGC35HD | C83: 2025 | D83: XUG035HDAKFC00524 | E83: 35 TON | F83: CC-02 | G83: CC-00002 | H83: WUR EW | I83: 41752500
...

Sheet UNIT STANDBY
A3: No | B3: Nama Asset | C3: Tahun Beli | D3: Tahun | E3: LOKASI | F3: STATUS | G3: Next Action | H3: Harga Jual | I3: Target Penyelesaian | J3: SN/ Plat Kendaraan | K3: Nomor Lambung Aktual
A4: 1 | B4: Bomag Smooth Drum Compactor BW211D-40 SL | D4: 2020 | E4: YARD DURI | F4: OTW DURI | G4: SEWA HKI | J4: 961582391008 | K4: VIBRO BW BRA-01
A5: 2 | B5: Bomag Smooth Drum Compactor BW211D-40SL | D5: 2021 | E5: YARD DURI | F5: OTW DURI | G5: SEWA HKI | J5: 961582391145 | K5: VIBRO BW BRA-03
A6: 3 | B6: Bomag Smooth Drum BW211D-40 | D6: 2022 | E6: YARD DURI | F6: OTW DURI | G6: SEWA HKI | J6: 961884302060 | K6: VIBRO BW BRA-06
A7: 4 | B7: Bomag Pad Foot Compactor BW211D-40 | D7: 2022 | E7: YARD DURI | F7: OTW DURI | G7: SEWA HKI | J7: 961884301016 | K7: VIBRO BW BRA-02
A8: 5 | B8: Bomag Smooth Drum Compactor BW211D-40SL | D8: 2022 | E8: YARD DURI | F8: OTW DURI | G8: SEWA HKI | J8: 961582391103 | K8: VIBRO BW BRA-07
A9: 6 | B9: Dumptruck FUSO FM 517 HS | D9: 2019 | E9: PROSES WTT | F9: OTW DURI | G9: WTT RWI | I9: 45 hari (24 April 2026) | J9: BK8119EO | K9: BRA-48
A10: 7 | B10: Dumptruck FUSO FM 517 HS | D10: 2019 | E10: PROSES WTT | F10: OTW DURI | G10: WTT RWI | I10: 45 hari (24 April 2026) | J10: BK8117EO | K10: BRA-49
A11: 8 | B11: Bomag Pad Foot Compactor BW211D-40 | D11: 2022 | E11: YARD DURI | F11: MASIH KERJA WUR | G11: BALIK KE YARD | I11: 5 MARET 2026 | J11: 961582391152 | K11: PF-00003
A12: 9 | B12: Excavator PC 210-10M0/P1 | D12: 2020 | F12: SEWA PAK KELMI | G12: SEWA | I12: 15 MARET 2026 | J12: C01531 | K12: EXC-00008
A13: 10 | B13: Excavator Caterpillar 305.5E2 | C13: 2023 | D13: 2023 | E13: YARD DURI | F13: STANDBY YARD | G13: JUAL/ SEWA | H13: 500jt | J13: WE217079
A14: 11 | B14: Excavator Caterpillar 305.5E2 | C14: 2023 | D14: 2023 | E14: YARD DURI | F14: STANDBY YARD | G14: JUAL/ SEWA | H14: 500jt | J14: WE217080
A15: 12 | B15: Dump Truck FUSO FN527ML | D15: 2016 | E15: YARD DURI | F15: PROSES PREMOBRWI | G15: PROSES PREMOBRWI | I15: 15 MARET 2026 | J15: BM8621 QU
A16: 13 | B16: Bulldozer Komatsu D85ESS-2 | C16: 2022 | D16: 2013 | E16: YARD DURI | F16: STANDBY YARD | G16: JUAL | H16: 550jt | J16: J16298
A17: 14 | B17: Bulldozer Caterpillar D6R | C17: 2022 | D17: 2011 | E17: YARD DURI | F17: STANDBY YARD | G17: JUAL | H17: 450jt | J17: S6X00348
A18: 15 | B18: Bulldozer Caterpillar D6G 2XL | D18: 2012 | E18: YARD DURI | F18: MASIH KERJA WUR | G18: BALIK KE YARD | I18: 5 MARET 2026 | J18: P6G01656 | K18: DZ-00002
A19: 16 | B19: Bulldozer Caterpillar D6G 2XL | D19: 2012 | E19: YARD DURI | F19: STANDBY YARD (Perbaikan) | J19: P6G01529 | K19: DZ-00003
A20: 17 | B20: Excavator CAT 320 GX new | D20: 2022 | E20: ROHUL | F20: SEWA PAK KELMI | G20: SEWA | I20: 15 MARET 2026 | J20: SYW01364 | K20: EXC-00005
A21: 18 | B21: Dump Truck HINO RANGER-FM 260 JD | D21: 2019 | E21: YARD DURI | J21: BG8976IX | K21: DT-00031
A22: 19 | B22: Dump Truck HINO RANGER-FM 260 JD | D22: 2019 | E22: YARD DURI | J22: BG 8535 OW | K22: DT-00032
A23: 20 | B23: Dump Truck HINO RANGER-FM 260 JD | D23: 2018 | E23: YARD DURI | J23: B9642KYW | K23: DT-00052
A24: 21 | B24: Dump Truck HINO RANGER-FM 260 JD | D24: 2018 | E24: YARD DURI | J24: B9644KYW | K24: DT-00053
A25: 22 | B25: Dump Truck HINO RANGER-FM 260 JD | D25: 2018 | E25: YARD DURI | J25: B9683KYW | K25: DT-00054
A26: 23 | B26: Dump Truck HINO RANGER-FM 260 JD | D26: 2016 | E26: YARD DURI | J26: B9701PYW | K26: DT-00055
A27: 24 | B27: Dump Truck HINO RANGER-FM 260 JD | D27: 2019 | E27: YARD DURI | J27: B9914 JYT | K27: DT-00057
A28: 25 | B28: Dump Truck HINO RANGER-FM 260 JD | D28: 2018 | E28: YARD DURI | J28: B9973 BIS / B9136PYX | K28: DT-00058
A29: 26 | B29: Dump Truck FUSO FN62F HD | D29: 2019 | E29: YARD DURI | J29: BG 8163 NK | K29: DT-00059
A30: 27 | B30: Dump Truck HINO RANGER-FM 260 JD | D30: 2019 | E30: YARD DURI | J30: BG 8230 MX | K30: DT-00060
A31: 28 | B31: Dump Truck HINO RANGER-FM 260 JD | D31: 2018 | E31: YARD DURI | J31: BG 8367 IJ | K31: DT-00061
A32: 29 | B32: Dump Truck HINO RANGER-FM 260 JD | D32: 2019 | E32: YARD DURI | J32: BG 8639 NI / XENNA 33 | K32: DT-00063
... A44: 41 | B44: Dump Truck HINO RANGER-FM 280 JD | D44: 2022 | E44: YARD DURI | J44: BM9398JO | K44: DT-04025
A45: 42 | B45: Bulldozer Caterpillar D6G | C45: 2022 | D45: 2006 | E45: YARD PRABUMULIH | F45: KERJA PRABUMULIH | G45: JUAL/ SEWA | H45: 400jt | J45: P6G00163 | K45: BRA-01
A46: 43 | B46: Bulldozer Caterpillar D7G2 | C46: 2022 | D46: 2010 | E46: YARD PRABUMULIH | F46: YARD PRABUMULIH | G46: JUAL/ SEWA | H46: 450jt-580jt | J46: 7MB05410 | K46: BRA-07
A47: 44 | B47: Excavator Caterpillar 320D S/N | C47: 2020 | D47: 2012 | E47: YARD PRABUMULIH | F47: YARD PRABUMULIH | G47: JUAL/ SEWA | H47: 385jt-650jt | J47: BZP03563 | K47: BRA-04
A48: 45 | B48: Excavator Caterpillar 320 GC | D48: 2022 | E48: YARD PRABUMULIH | F48: YARD PRABUMULIH | J48: DKJ40199 | K48: BRA-10
A49: 46 | B49: Excavator Caterpillar 320 GC | D49: 2022 | E49: YARD PRABUMULIH | F49: YARD PRABUMULIH | J49: DKJ40200 | K49: BRA-11
A50: 47 | B50: Excavator Caterpillar 320 GC | D50: 2022 | E50: YARD PRABUMULIH | F50: YARD PRABUMULIH | J50: DKJ40263 | K50: BRA-14
A51: 48 | B51: Excavator Caterpillar 320 GC | D51: 2022 | E51: YARD PRABUMULIH | F51: KERJA PRABUMULIH | G51: BALIK KE YARD PRABUMULIH | I51: 6 MARET 2026 | J51: DKJ40294 | K51: BRA-15
A52: 49 | B52: Excavator PC 210-10M0/P1 | D52: 2025 | E52: YARD PRABUMULIH | F52: KERJA PRABUMULIH | G52: BALIK KE YARD PRABUMULIH | I52: 6 MARET 2026 | J52: C00637 | K52: BRA-26
A53: 50 | B53: Dumptruck Isuzu NMR 81 | D53: 2023 | E53: YARD PRABUMULIH | F53: YARD PRABUMULIH | J53: B9097ZYT | K53: BRA-45
...

Sheet Copy of List Data Aset BRA 3
A2: REKAP HEAVY EQUIPMENT DAN VEHICLE PT BINA REKAYASA ANUGRAH
A4: No | B4: Nama Asset | C4: Dealer | D4: Tahun | E4: SN/ Plat Kendaraan | F4: Status Warranty | G4: PIC | H4: Kode Unit | I4: Nomor Lambung Aktual | J4: PROJECT | K4: LOKASI
A5: 1 | B5: Bomag Smooth Drum Compactor BW211D-40SL | C5: United Tractors | D5: 2024 | E5: 961582391660 | F5: voucher parts ut | H5: SD 08 | J5: ASR | K5: YARD
A6: 2 | B6: Excavator Komatsu PC 200-10 MOCE | C6: United Tractors | D6: 2022 | E6: DBCHO380 | F6: waranty ut | H6: Exca 12 | I6: BRA-12 | J6: ASR | K6: YARD
A7: 3 | B7: Excavator Caterpillar 305.5E2 | C7: Trakindo | D7: 2023 | E7: WE217082 | F7: tidak waranty | H7: Exca 19 | I7: HE-6.003 | J7: ASR | K7: YARD
A8: 4 | B8: MITSUBISHI TRITON | D8: 2024 | E8: BM8926QJ | H8: TR7 | J8: ASR | K8: YARD
A9: 5 | B9: TOYOTA HILUX | D9: 2022 | E9: B9153ZBA | J9: ASR | K9: YARD
A10: 6 | B10: TOYOTA HILUX | D10: 2022 | E10: B9135ZBA | J10: ASR | K10: YARD
A11: 7 | B11: INOVA | D11: 2022 | E11: B1167 ZKS | G11: Sepra | H11: IN1 | J11: DURI | K11: PINJAM
A12: 8 | B12: MOTOR BEAT | D12: 2016 | H12: M1 | J12: DURI
A13: 9 | B13: MOTOR VEGA R | D13: 2018 | E13: BM2843 BA | H13: M2 | J13: DURI
A14: 10 | B14: CRF150L | D14: 2024 | E14: BM6446ABZ | H14: MC001 | J14: DURI
A15: 11 | B15: CRF150L | D15: 2024 | E15: BM6449ABZ | H15: MC004 | J15: DURI
A16: 12 | B16: CRF150L | D16: 2024 | E16: BM6452ABZ | H16: MC006 | J16: DURI
A17: 8 | B17: Wheel Loader SEM 655D (Pallet Fork) | C17: Tri Swardana Utama | D17: 2024 | E17: S5512759 | F17: Warranty - 2000 | H17: WL 02 | I17: WL-31001 | J17: MATTING BOARD | K17: YARD
A18: 9 | B18: FLATBED FUSO FN62FL | D18: 2025 | E18: BM8450NU | H18: FD-01 | I18: FBT-31003 | J18: MATTING BOARD | K18: YARD
A19: 10 | B19: FLATBED FUSO FN62FL | D19: 2025 | E19: BM8451NU | H19: FD-02 | I19: FBT-31004 | J19: MATTING BOARD | K19: YARD
A20: 11 | B20: FLATBED FUSO FN62FL | D20: 2025 | E20: BM8534NU | H20: FD-03 | I20: FBT-31006 | J20: MATTING BOARD | K20: YARD
A21: 12 | B21: FLATBED FUSO FN62FL | D21: 2025 | E21: BM8532NU | H21: ASET TWS | I21: FBT-31005 | J21: MATTING BOARD | K21: YARD
A22: 13 | B22: FLATBED | D22: 2025 | E22: BM8442NU | H22: ASET TWS | I22: FBT-31001 | J22: MATTING BOARD | K22: YARD
A23: 14 | B23: FLATBED | D23: 2025 | E23: BM8443NU | H23: ASET TWS | I23: FBT-31002 | J23: MATTING BOARD | K23: YARD
A24: 15 | B24: TMC FUSO FN62FL / TADANO TM-ZT1005H | D24: 2025 | E24: BM8449NU / KZ1263 | H24: TMC02 | I24: TMC-31003 | J24: MATTING BOARD | K24: YARD
A25: 16 | B25: TMC FUSO FN62FL / TADANO TM-ZT1005H | D25: 2025 | E25: BM8452NU / KZ1255 | H25: TMC03 | I25: TMC-31004 | J25: MATTING BOARD | K25: YARD
A26: 17 | B26: TMC FUSO FN62FL / TADANO TM-ZT1005H | D26: 2025 | E26: BM8533NU | H26: TMC04 | I26: TMC-31006 | J26: MATTING BOARD | K26: YARD
A27: 18 | B27: TMC FUSO FN62FL / TADANO TM-ZT1005H | D27: 2025 | E27: BM8531NU | H27: ASET TWS | I27: TMC-31005 | J27: MATTING BOARD | K27: YARD
A28: 19 | B28: TMC | D28: 2025 | E28: BM8440NU | H28: ASET TWS | I28: TMC-31001 | J28: MATTING BOARD | K28: YARD
A29: 20 | B29: TMC | D29: 2025 | E29: BM8441NU | H29: ASET TWS | I29: TMC-31002 | J29: MATTING BOARD | K29: YARD
A30: 21 | B30: TOYOTA HILUX | D30: 2025 | E30: B9225 ZBA | G30: Affan | J30: MATTING BOARD | K30: YARD
A31: 22 | B31: TOYOTA HILUX | D31: 2025 | E31: B9227 ZBA | G31: Fathur | J31: MATTING BOARD | K31: PINJAM
A32: 23 | B32: TOYOTA HILUX | D32: 2025 | E32: B9725UBE | G32: Boby Eko | J32: MATTING BOARD | K32: PINJAM
A33: 24 | B33: TOYOTA HILUX | D33: 2025 | E33: B9688UBE | J33: MATTING BOARD | K33: YARD
A34: 25 | B34: AVANZA | D34: 2022 | E34: B1691ZKW | G34: Guswan Arizal | H34: AV 3 | J34: OPS EQUIPMENT | K34: PINJAM
A35: 26 | B35: MITSUBISHI TRITON | D35: 2018 | E35: BM9834 DK | G35: Dany Agung | H35: TR 1 | J35: OPS EQUIPMENT | K35: KANTOR PKU
A36: 27 | B36: SUZUKI /NEW CARRY PU FD AC PS | D36: 2022 | E36: BK8722 FE | G36: Mekanik | H36: P1 | J36: OPS EQUIPMENT | K36: YARD
A37: 28 | B37: PICK UP KIJANG | D37: 2006 | E37: B9790 JY | G37: Mekanik | H37: P2 | J37: OPS EQUIPMENT | K37: YARD
A38: 29 | B38: MITSUBISHI TRITON | D38: 2024 | E38: BM8430QK | G38: fajar | H38: TR11 | J38: OPS EQUIPMENT | K38: YARD
A39: 30 | B39: AVANZA | D39: 2022 | E39: B1693ZKW | G39: ops Office Duri | H39: AV 1 | J39: OPS OFFICE DURI | K39: KANTOR PKU
A40: 31 | B40: AVANZA | D40: 2022 | E40: B1695ZKW | G40: Ilham Syadikin | H40: AV 2 | J40: OPS OFFICE DURI | K40: PINJAM
A41: 32 | B41: Dump Truck FUSO FN527ML | D41: 2016 | E41: BM8621 QU | H41: DT 108 | J41: PROSES PREMOB | K41: YARD
A42: 33 | B42: CAT Smoothdrum CS10GC | C42: Trakindo | D42: 2022 | E42: T8F00361 | F42: tidak waranty | H42: PF 04 | I42: SD-41002 | J42: RWI | K42: YARD
...

Sheet Sheet27
A2: NO | B2: KENDARAAN OPERASIONAL | C2: TAHUN | D2: PLAT | E2: PIC | F2: JABATAN | G2: PROJECT
A3: 1 | B3: NISSAN X-TRAIL | C3: 2006 | D3: BM1707 DN / BM1098 LLT | E3: PAK ZAHRIAL | F3: ORG TUA KOMISARIS | G3: PEKANBARU
A4: 2 | B4: INOVA | C4: 2022 | D4: B1167 ZKS | E4: Sepra | F4: GM | G4: DURI
A5: 3 | B5: INOVA | C5: 2021 | D5: B1869 ZKV | E5: HO | G5: HO
A6: 4 | B6: AVANZA | C6: 2022 | D6: B1693ZKW | E6: Monika | F6: CEM | G6: OPS OFFICE DURI
A7: 5 | B7: AVANZA | C7: 2022 | D7: B1695ZKW | E7: Ilham Syadikin | F7: HRD | G7: OPS OFFICE DURI
A8: 6 | B8: AVANZA | C8: 2022 | D8: B1691ZKW | E8: Guswan Arizal | F8: EQUIPMENT | G8: OPS EQUIPMENT
A9: 7 | B9: AVANZA | C9: 2022 | D9: B1689ZKW | E9: Rahmat | F9: PM | G9: SBY YARD DURI
A10: 8 | B10: MITSUBISHI TRITON | C10: 2018 | D10: BM9834 DK | E10: Dany Agung | F10: HE | G10: OPS EQUIPMENT
A11: 9 | B11: MITSUBISHI TRITON | C11: 2018 | D11: BM9833 DK | E11: Mekanik Prabumulih | F11: MEKANIK | G11: PERTAMINA EP
A12: 10 | B12: MITSUBISHI TRITON | C12: 2016 | D12: BP 8521 DJ | E12: Mekanik Prabumulih | F12: MEKANIK | G12: PERTAMINA EP
A13: 11 | B13: TOYOTA HILUX | C13: 2022 | D13: B9133ZBA | E13: Tommy | G13: WUR EW
A14: 12 | B14: MITSUBISHI TRITON | C14: 2024 | D14: BM8777QJ | E14: Rikson | G14: WUR EW
A15: 13 | B15: MITSUBISHI TRITON | C15: 2024 | D15: BM8776QJ | E15: Agung | G15: WUR EW
A16: 14 | B16: MITSUBISHI TRITON | C16: 2024 | D16: BM8925QJ | E16: Jhon Peris | G16: WUR EW
A17: 15 | B17: MITSUBISHI TRITON | C17: 2024 | D17: BM8926QJ | G17: WUR EW
A18: 16 | B18: MITSUBISHI TRITON | C18: 2024 | D18: BM8774QJ | E18: Desta | F18: PM | G18: PERTAMINA EP
A19: 17 | B19: MITSUBISHI TRITON | C19: 2024 | D19: BM8775QJ | E19: Nikson | G19: PERTAMINA EP
A20: 18 | B20: TOYOTA HILUX | C20: 2025 | D20: BG8782PS | E20: User PHR | G20: ADERA
A21: 19 | B21: TOYOTA HILUX | C21: 2025 | D21: BG8779PS | E21: User PHR | G21: ADERA
A22: 20 | B22: TOYOTA HILUX | C22: 2025 | D22: BG8776PS | E22: User PHR | G22: ADERA
A23: 21 | B23: MITSUBISHI TRITON | C23: 2025 | D23: BM8468 QN | E23: Harino | G23: WUR EW
A24: 22 | B24: MITSUBISHI TRITON | C24: 2025 | D24: BM8469 QN | E24: Iswandi | G24: WUR EW
A25: 23 | B25: SUZUKI /NEW CARRY PU FD AC PS | C25: 2022 | D25: BK8722 FE | E25: Afriyandi | F25: MEKANIK | G25: OPS EQUIPMENT
A26: 24 | B26: PICK UP KIJANG | C26: 2006 | D26: B9790 JY | E26: Mekanik | F26: MEKANIK | G26: OPS EQUIPMENT
A27: 25 | B27: ISUZU PANTHER PICKUP | C27: 2005 | D27: BK8333 BF | E27: PAK ZAHRIAL | F27: ORG TUA KOMISARIS | G27: PEKANBARU
A28: 26 | B28: PICK UP SUZUKI CARRY | C28: 2022 | D28: B9305 ZAE | E28: Eryanto | F28: PMT CEM | G28: OPS EQUIPMENT
A29: 27 | B29: MITSUBISHI TRITON | C29: 2024 | D29: BM8430QK | E29: Jhoni Septian | F29: MEKANIK | G29: OPS EQUIPMENT
A30: 28 | B30: MITSUBISHI TRITON | C30: 2024 | D30: BM8429QK | E30: Roni (Qc) | G30: WELLPAD
A31: 29 | B31: TOYOTA HILUX | C31: 2024 | D31: B9186ZBA | E31: Reki | G31: WUR EW
A32: 30 | B32: TOYOTA HILUX | C32: 2024 | D32: B9188ZBA | E32: Junika | G32: WUR EW
A33: 31 | B33: BYD | C33: 2025 | D33: B1082 ZNP | E33: KANTOR CABANG | G33: KANTOR CABANG
A34: 32 | B34: PAJERO | C34: 2025 | D34: BG 1392 PD | E34: SEWA PERTAMINA EP | G34: ADERA
A35: 33 | B35: INNOVA ZENIX | C35: 2025 | D35: B1866 ZOF | E35: HO | G35: HO
A36: 34 | B36: INNOVA ZENIX | C36: 2025 | D36: B1864 ZOF | E36: HO | G36: HO
A37: 35 | B37: TOYOTA HILUX | C37: 2022 | D37: B9147ZBA | E37: Mardimal | G37: WUR EW
A38: 36 | B38: TOYOTA HILUX | C38: 2022 | D38: B9146ZBA | E38: Solihin | G38: WUR EW
A39: 37 | B39: TOYOTA HILUX | C39: 2022 | D39: B9144ZBA | E39: Boyson | G39: WUR EW
A40: 38 | B40: TOYOTA HILUX | C40: 2022 | D40: B9142ZBA | E40: Triandi | G40: WUR EW
A41: 39 | B41: TOYOTA HILUX | C41: 2022 | D41: B9115ZBA | E41: Ilham Ramadhan | G41: WUR EW
...

Sheet Aset BRA - Revised
A3: HEAVY EQUIPMENT DAN VEHICLE PT BINA REKAYASA ANUGRAH
P5: Nama Asset | Q5: Tahun | R5: SN/ Plat Kendaraan | S5: Kapasitas | T5: lokasi
B6: Year | C6: Nama Asset | D6: Tahun | E6: SN/ Plat Kendaraan | P6: VIBROROLLER
P7: 2020 | Q7: Bomag Smooth Drum Compactor BW211D-40 SL | R7: 961582391008 | S7: 138 HP / 103 kW | T7: PERTAMINA EP
P8: 2020 | Q8: Bomag Smooth Drum Compactor BW211D-40 | R8: 961582391036 | S8: 138 HP / 103 kW | T8: WUR EW
P9: 2021 | Q9: Bomag Smooth Drum Compactor BW211D-40SL | R9: 961582391145 | S9: 138 HP / 103 kW | T9: PERTAMINA EP
P10: 2022 | Q10: Bomag Smooth Drum Compactor BW211D-40 | R10: 961884301945 | S10: 138 HP / 103 kW | T10: WUR EW
P11: 2022 | Q11: Bomag Smooth Drum BW211D-40 | R11: 961884302060 | S11: 138 HP / 103 kW | T11: PERTAMINA EP
P12: 2022 | Q12: Bomag Pad Foot Compactor BW211D-40 | R12: 961884301016 | S12: 138 HP / 103 kW | T12: PERTAMINA EP
P13: 2022 | Q13: Bomag Pad Foot Compactor BW211D-40 | R13: 961884301614 | S13: 138 HP / 103 kW | T13: WUR EW
P14: 2022 | Q14: Bomag Pad Foot Compactor BW211D-40SL | R14: 961582391152 | S14: 138 HP / 103 kW | T14: WUR EW
P15: 2022 | Q15: CAT Pad Foot CS10GC | R15: T8F00361 | S15: 111 HP / 83 kW | T15: PERTAMINA EP
P16: 2022 | Q16: Bomag Smooth Drum Compactor BW211D-40SL | R16: 961582391103 | S16: 138 HP / 103 kW | T16: PERTAMINA EP
P17: 2024 | Q17: Bomag Smooth Drum Compactor BW211D-40SL | R17: 961582391660 | S17: 138 HP / 103 kW | T17: WELLPAD
